<?xml version="1.0"?>
<robot name="willand">

  <material name="white">
    <color rgba="1 1 1 1"/>
  </material>
  <material name="black">
    <color rgba="0 0 0 1"/>
  </material>
  <material name="blue">
    <color rgba="0 0 0.8 1"/>
  </material>
  <material name="green">
    <color rgba="0 1 0 1"/>
  </material>

  <link name="base_link">
    <visual>
      <geometry>
        <mesh
          filename="package://willand_description/meshes/Body.STL" />
      </geometry>
        <origin rpy="1.5705 0 0" xyz="-0.25 0.1675 -0.0075"/>
      <material name="white"/>
    </visual>
    <collision>
      <geometry>
        <box size="0.5 0.3 0.07"/>
      </geometry>
      <origin rpy="0 0 0" xyz="0 0 0.035"/>
    </collision>
    <inertial>
      <origin xyz="-0.00509 0 0.03461" rpy="0 0 0"/>
      <mass value="65.8282"/>
      <inertia
        ixx="63.621330" ixy="11.057206" ixz="0.021099"
        iyy="187.798863" iyz="-0.003735"
        izz="169.286082"/>
    </inertial>
  </link>

  <link name="wheel_1">
    <visual>
      <geometry>
        <mesh
          filename="package://willand_description/meshes/Wheel.STL" />
      </geometry>
      <origin rpy="1.5705 0 0" xyz="-0.055 0 -0.055 "/>
      <material name="black"/>
    </visual>
    <collision>
      <geometry>
        <cylinder length="0.015" radius="0.055"/>
      </geometry>
      <origin rpy="1.5705 0 0" xyz="0 -0.0075 0"/>
    </collision>
    <inertial>
      <origin xyz="0 -0.0075 0" rpy="0 0 0"/>
      <mass value="1.0252"/>
      <inertia
        ixx="0.09065214" ixy="0.0" ixz="0.0"
        iyy="0.09065214" iyz="0.0"
        izz="0.17745989"/>
    </inertial>
  </link> 

  <link name="wheel_2">
    <visual>
      <geometry>
        <mesh
          filename="package://willand_description/meshes/Wheel.STL" />
      </geometry>
      <origin rpy="1.5705 0 0" xyz="-0.055 0 -0.055"/>
      <material name="black"/>
    </visual>
    <collision>
      <geometry>
        <cylinder length="0.015" radius="0.055"/>
      </geometry>
      <origin rpy="1.5705 0 0" xyz="0 -0.0075 0"/>
    </collision>
    <inertial>
      <origin xyz="0 -0.0075 0" rpy="0 0 0"/>
      <mass value="1.252"/>
      <inertia
        ixx="0.09065214" ixy="0.0" ixz="0.0"
        iyy="0.09065214" iyz="0.0"
        izz="0.17745989"/>
    </inertial>
  </link> 

  <link name="wheel_3">
    <visual>
      <geometry>
        <mesh
          filename="package://willand_description/meshes/Wheel.STL" />
      </geometry>
      <origin rpy="1.5705 0 0" xyz="-0.055 0 -0.055"/>
      <material name="black"/>
    </visual>
    <collision>
      <geometry>
        <cylinder length="0.015" radius="0.055"/>
      </geometry>
      <origin rpy="1.5705 0 0" xyz="0 -0.0075 0"/>
    </collision>
    <inertial>
      <origin xyz="0 -0.0075 0" rpy="0 0 0"/>
      <mass value="1.252"/>
      <inertia
        ixx="0.09065214" ixy="0.0" ixz="0.0"
        iyy="0.09065214" iyz="0.0"
        izz="0.17745989"/>
    </inertial>
  </link> 

  <link name="wheel_4">
    <visual>
      <geometry>
        <mesh
          filename="package://willand_description/meshes/Wheel.STL" />
      </geometry>
      <origin rpy="1.5705 0 0" xyz="-0.055 0 -0.055"/>
      <material name="black"/>
    </visual>
    <collision>
      <geometry>
        <cylinder length="0.015" radius="0.055"/>
      </geometry>
      <origin rpy="1.5705 0 0" xyz="0 -0.0075 0"/>
    </collision>
    <inertial>
      <origin xyz="0 -0.0075 0" rpy="0 0 0"/>
      <mass value="1.252"/>
      <inertia
        ixx="0.09065214" ixy="0.0" ixz="0.0"
        iyy="0.09065214" iyz="0.0"
        izz="0.17745989"/>
    </inertial>
  </link> 

  <joint name="joint_base_wheel1" type="continuous">
    <origin rpy="0 0 0" xyz="0.13189 -0.1525 0.03018 "/>
    <axis rpy="0 0 0" xyz="0 1 0"/>
    <parent link="base_link"/>
    <child link="wheel_1"/>
  </joint>

  <joint name="joint_base_wheel2" type="continuous">
    <origin rpy="0 0 0" xyz="-0.13211 -0.1525 0.03018 "/>
    <axis rpy="0 0 0" xyz="0 1 0"/>
    <parent link="base_link"/>
    <child link="wheel_2"/>
  </joint>

  <joint name="joint_base_wheel3" type="continuous">
    <origin rpy="0 0 0" xyz="0.13189 0.1675 0.03018 "/>
    <axis rpy="0 0 0" xyz="0 1 0"/>
    <parent link="base_link"/>
    <child link="wheel_3"/>
  </joint>

  <joint name="joint_base_wheel4" type="continuous">
    <origin rpy="0 0 0" xyz="-0.13211 0.1675 0.03018 "/>
    <axis rpy="0 0 0" xyz="0 1 0"/>
    <parent link="base_link"/>
    <child link="wheel_4"/>
  </joint>

</robot>
